## 以下代码输出顺序是什么？为什么会这样？   
```
try {
   let a = 0;
   (async function() {
       a += 1;
       console.log('inner', a);
       throw new Error('123');   
   })()
   console.log('outer', a)
} catch(e) {
    console.warn('Error', e);
}
```
   
#### 输出结果：   
```
inner 1
outer 1
Uncaught(in promise) Error: 123
```   
   
async的函数内部代码实际也还是同步的   
可以理解为   
```
function a() {
    return new Promise(function(resolve, reject) {
        a += 1;
        console.log('inner', a);
        throw new Error('123')    
    })
}
```